WARNING  celery.redirected:log.py:227 ^--2--^^--2--^^--2--^^--2--^^--2--^^--2--^^--2--^^--2--^^--2--^^--2--^^--2--^^--2--^^--2--^^--2--^^--2--^^--2--^^--2--^^--2--^^--2--^^--2--^
WARNING  celery.redirected:log.py:227 log_dir:../logs
WARNING  celery.redirected:log.py:227 folder exist!
WARNING  celery.redirected:log.py:227 INFO     root:mylogger.py:78 case用例:12客诉工单列表,当前责任是本人-已关闭
INFO     root:mylogger.py:78 case用例:12客诉工单列表,当前责任是本人-已关闭
WARNING  celery.redirected:log.py:227 [2021-06-09 19:59:49,169] | mylogger.py |INFO  : case用例:12客诉工单列表,当前责任是本人-已关闭
WARNING  celery.redirected:log.py:227 log_dir:../logs
WARNING  celery.redirected:log.py:227 folder exist!
WARNING  celery.redirected:log.py:227 INFO     root:mylogger.py:78 地址url：https://test.xlvren.com/bp/workOrderList
INFO     root:mylogger.py:78 地址url：https://test.xlvren.com/bp/workOrderList
WARNING  celery.redirected:log.py:227 [2021-06-09 19:59:49,170] | mylogger.py |INFO  : 地址url：https://test.xlvren.com/bp/workOrderList
WARNING  celery.redirected:log.py:227 log_dir:../logs
WARNING  celery.redirected:log.py:227 folder exist!
WARNING  celery.redirected:log.py:227 INFO     root:mylogger.py:78 token：892c8394-53ac-44bd-af3b-91394f8583aa
INFO     root:mylogger.py:78 token：892c8394-53ac-44bd-af3b-91394f8583aa
WARNING  celery.redirected:log.py:227 [2021-06-09 19:59:49,171] | mylogger.py |INFO  : token：892c8394-53ac-44bd-af3b-91394f8583aa
WARNING  celery.redirected:log.py:227 header :{'Authorization': 'Bearer 892c8394-53ac-44bd-af3b-91394f8583aa', 'Content-Type': 'application/json'}
WARNING  celery.redirected:log.py:227 method :get
WARNING  celery.redirected:log.py:227 pararm :{"page":1,"size":2,"status":2}
WARNING  celery.redirected:log.py:227 log_dir:../logs
WARNING  celery.redirected:log.py:227 folder exist!
WARNING  celery.redirected:log.py:227 DEBUG    root:mylogger.py:80 get 请求 ....
DEBUG    root:mylogger.py:80 get 请求 ....
WARNING  celery.redirected:log.py:227 [2021-06-09 19:59:49,172] | mylogger.py |DEBUG : get 请求 ....
WARNING  celery.redirected:log.py:227 DEBUG    urllib3.connectionpool:connectionpool.py:975 Starting new HTTPS connection (1): test.xlvren.com:443
DEBUG    urllib3.connectionpool:connectionpool.py:975 Starting new HTTPS connection (1): test.xlvren.com:443
WARNING  celery.redirected:log.py:227 DEBUG    urllib3.connectionpool:connectionpool.py:461 https://test.xlvren.com:443 "GET /bp/workOrderList?page=1&size=2&status=2 HTTP/1.1" 200 None
DEBUG    urllib3.connectionpool:connectionpool.py:461 https://test.xlvren.com:443 "GET /bp/workOrderList?page=1&size=2&status=2 HTTP/1.1" 200 None
WARNING  celery.redirected:log.py:227 log_dir:../logs
WARNING  celery.redirected:log.py:227 folder exist!
WARNING  celery.redirected:log.py:227 DEBUG    root:mylogger.py:80 测试结果:get,,,{'errorCode': 0, 'data': []}
DEBUG    root:mylogger.py:80 测试结果:get,,,{'errorCode': 0, 'data': []}
WARNING  celery.redirected:log.py:227 [2021-06-09 19:59:49,319] | mylogger.py |DEBUG : 测试结果:get,,,{'errorCode': 0, 'data': []}
WARNING  celery.redirected:log.py:227 get 请求结束。。。。。。